Workbook

Sheet Read Me
A1: NZ 2026 election — poll tracker & party-vote leverage model
A2: Updated 14 Oct 2026 for the 7 Nov 2026 general election. Poll data current to 13 Oct 2026 (latest: 1News–Verian, 8–12 Oct).
A4: What it answers
A5: Under MMP, seats are shared out with the Sainte-Laguë formula. At any moment one party is 'next in line' for the 121st seat. A party vote for that party is the one most likely to add an MP; a vote for a party far from its next seat, or below 5% with no electorate, is much less likely to change the seat count.
A7: Tabs
A8: Seat Calculator — pick 'Average' or any poll, optionally add a what-if adjustment, and see seats, the gap to each party's next seat, and a verdict.
A9: Poll-by-Poll — every poll run through the same engine, plus a summary of how often each party is next in line or close to a seat.
A10: Polls — the data. Add new polls in the blank blue rows; set Include = Y to put them in the average.
A11: Pollster Methods — how each company polls (phone, online, sampling), with what's verified vs to-check.
A12: Settings — seats, 5% threshold, vote-count estimate, 'close' thresholds, and the electorate seats each party is assumed to win.
A13: Engine — the Sainte-Laguë calculation (60 divisors per party per poll). No need to touch it.
A15: Colour legend
... A25: Wikipedia, 'Opinion polling for the 2026 New Zealand general election' (accessed 14 Oct 2026); RNZ (RNZ–Reid Research poll, 6 Oct 2026); 1News (1News–Verian polls, 6 and 13 Oct 2026); Roy Morgan (September 2026 NZ poll); interest.co.nz and NZ Herald (Taxpayers' Union–Curia, 9 Oct 2026). Method: Electoral Act 1993 Sainte-Laguë allocation, as used by the Electoral Commission's MMP seat calculator.

Sheet Seat Calculator
A1: MMP seat calculator — which party vote is closest to adding a seat?
A3: Scenario (pick 'Average' or a poll ID): | C3: Average
A4: Optional: type a what-if adjustment in column D (e.g. 0.5% to give a party half a point more).
A7: Party | B7: Code | C7: Poll share | D7: What-if adjustment (pp) | E7: Scenario share | F7: Electorates assumed | G7: In Parliament? | H7: List entitlement (seats) | I7: Final seats | J7: Overhang seats | K7: Gap to next seat (pp of total vote) | L7: ≈ extra party votes needed | M7: Progress to next seat | N7: Cushion before losing a seat (pp) | O7: Verdict | P7: Leverage rank (1 = closest to +1 seat) | Q7: Bloc
A8: National | B8: NAT | C8: =IF($C$3="Average",N(Polls!H37),IFERROR(N(INDEX(Polls!H$6:H$35,MATCH($C$3,Polls!$A$6:$A$35,0))),0)) -> 0.28488889 | D8: 0 | E8: =MAX(0,C8+D8) -> 0.28488889 | F8: =Settings!$C$14 -> 0 | G8: =IF(Engine!BT283="Next seat","Yes","No") -> Yes | H8: =Engine!BL283 -> 34 | I8: =Engine!BM283 -> 34 | J8: =MAX(0,I8-H8) -> 0 | K8: =Engine!BN283 -> 0.00031111111 | L8: =IF(K8="","",ROUND(K8*Settings!$B$6,-2)) -> 900 | M8: =Engine!BP283 -> 0.96236559 | N8: =Engine!BO283 -> 0.008257649 | O8: =IF(G8="No",IF(K8<=Settings!$B$9,"Below 5% but within reach","Below 5% — vote doesn't win a seat"),IF(K8<=Settings!$B$7,"Very close to +1 seat",IF(K8<=Settings!$B$8,"Close to +1 seat",IF(K8<=Settings!$B$9,"Possible +1 seat","Not near a seat")))) -> Very close to +1 seat | P8: =IF(G8="Yes",COUNTIFS($G$8:$G$14,"Yes",$K$8:$K$14,"<"&K8)+1,"") -> 1 | Q8: =Settings!D14 -> Govt
A9: Labour | B9: LAB | C9: =IF($C$3="Average",N(Polls!I37),IFERROR(N(INDEX(Polls!I$6:I$35,MATCH($C$3,Polls!$A$6:$A$35,0))),0)) -> 0.27933333 | D9: 0 | E9: =MAX(0,C9+D9) -> 0.27933333 | F9: =Settings!$C$15 -> 0 | G9: =IF(Engine!BT284="Next seat","Yes","No") -> Yes | H9: =Engine!BL284 -> 34 | I9: =Engine!BM284 -> 34 | J9: =MAX(0,I9-H9) -> 0 | K9: =Engine!BN284 -> 0.0058666667 | L9: =IF(K9="","",ROUND(K9*Settings!$B$6,-2)) -> 17000 | M9: =Engine!BP284 -> 0.29032258 | N9: =Engine!BO284 -> 0.0027020934 | O9: =IF(G9="No",IF(K9<=Settings!$B$9,"Below 5% but within reach","Below 5% — vote doesn't win a seat"),IF(K9<=Settings!$B$7,"Very close to +1 seat",IF(K9<=Settings!$B$8,"Close to +1 seat",IF(K9<=Settings!$B$9,"Possible +1 seat","Not near a seat")))) -> Possible +1 seat | P9: =IF(G9="Yes",COUNTIFS($G$8:$G$14,"Yes",$K$8:$K$14,"<"&K9)+1,"") -> 3 | Q9: =Settings!D15 -> Opposition
A10: Green | B10: GRN | C10: =IF($C$3="Average",N(Polls!J37),IFERROR(N(INDEX(Polls!J$6:J$35,MATCH($C$3,Polls!$A$6:$A$35,0))),0)) -> 0.14555556 | D10: 0 | E10: =MAX(0,C10+D10) -> 0.14555556 | F10: =Settings!$C$16 -> 3 | G10: =IF(Engine!BT285="Next seat","Yes","No") -> Yes | H10: =Engine!BL285 -> 18 | I10: =Engine!BM285 -> 18 | J10: =MAX(0,I10-H10) -> 0 | K10: =Engine!BN285 -> 0.0073777778 | L10: =IF(K10="","",ROUND(K10*Settings!$B$6,-2)) -> 21400 | M10: =Engine!BP285 -> 0.10752688 | N10: =Engine!BO285 -> 0.0010466989 | O10: =IF(G10="No",IF(K10<=Settings!$B$9,"Below 5% but within reach","Below 5% — vote doesn't win a seat"),IF(K10<=Settings!$B$7,"Very close to +1 seat",IF(K10<=Settings!$B$8,"Close to +1 seat",IF(K10<=Settings!$B$9,"Possible +1 seat","Not near a seat")))) -> Possible +1 seat | P10: =IF(G10="Yes",COUNTIFS($G$8:$G$14,"Yes",$K$8:$K$14,"<"&K10)+1,"") -> 5 | Q10: =Settings!D16 -> Opposition
A11: ACT | B11: ACT | C11: =IF($C$3="Average",N(Polls!K37),IFERROR(N(INDEX(Polls!K$6:K$35,MATCH($C$3,Polls!$A$6:$A$35,0))),0)) -> 0.096333333 | D11: 0 | E11: =MAX(0,C11+D11) -> 0.096333333 | F11: =Settings!$C$17 -> 2 | G11: =IF(Engine!BT286="Next seat","Yes","No") -> Yes | H11: =Engine!BL286 -> 12 | I11: =Engine!BM286 -> 12 | J11: =MAX(0,I11-H11) -> 0 | K11: =Engine!BN286 -> 0.007 | L11: =IF(K11="","",ROUND(K11*Settings!$B$6,-2)) -> 20300 | M11: =Engine!BP286 -> 0.15322581 | N11: =Engine!BO286 -> 0.0013703704 | O11: =IF(G11="No",IF(K11<=Settings!$B$9,"Below 5% but within reach","Below 5% — vote doesn't win a seat"),IF(K11<=Settings!$B$7,"Very close to +1 seat",IF(K11<=Settings!$B$8,"Close to +1 seat",IF(K11<=Settings!$B$9,"Possible +1 seat","Not near a seat")))) -> Possible +1 seat | P11: =IF(G11="Yes",COUNTIFS($G$8:$G$14,"Yes",$K$8:$K$14,"<"&K11)+1,"") -> 4 | Q11: =Settings!D17 -> Govt
A12: NZ First | B12: NZF | C12: =IF($C$3="Average",N(Polls!L37),IFERROR(N(INDEX(Polls!L$6:L$35,MATCH($C$3,Polls!$A$6:$A$35,0))),0)) -> 0.10333333 | D12: 0 | E12: =MAX(0,C12+D12) -> 0.10333333 | F12: =Settings!$C$18 -> 0 | G12: =IF(Engine!BT287="Next seat","Yes","No") -> Yes | H12: =Engine!BL287 -> 13 | I12: =Engine!BM287 -> 13 | J12: =MAX(0,I12-H12) -> 0 | K12: =Engine!BN287 -> 0.0082666667 | L12: =IF(K12="","",ROUND(K12*Settings!$B$6,-2)) -> 24000 | M12: =Engine!BP287 -> 0 | N12: =Engine!BO287 -> 0.00011272142 | O12: =IF(G12="No",IF(K12<=Settings!$B$9,"Below 5% but within reach","Below 5% — vote doesn't win a seat"),IF(K12<=Settings!$B$7,"Very close to +1 seat",IF(K12<=Settings!$B$8,"Close to +1 seat",IF(K12<=Settings!$B$9,"Possible +1 seat","Not near a seat")))) -> Possible +1 seat | P12: =IF(G12="Yes",COUNTIFS($G$8:$G$14,"Yes",$K$8:$K$14,"<"&K12)+1,"") -> 6 | Q12: =Settings!D18 -> Govt
A13: Te Pāti Māori | B13: TPM | C13: =IF($C$3="Average",N(Polls!M37),IFERROR(N(INDEX(Polls!M$6:M$35,MATCH($C$3,Polls!$A$6:$A$35,0))),0)) -> 0.0145 | D13: 0 | E13: =MAX(0,C13+D13) -> 0.0145 | F13: =Settings!$C$19 -> 4 | G13: =IF(Engine!BT288="Next seat","Yes","No") -> Yes | H13: =Engine!BL288 -> 2 | I13: =Engine!BM288 -> 4 | J13: =MAX(0,I13-H13) -> 2 | K13: =Engine!BN288 -> 0.0227 | L13: =IF(K13="","",ROUND(K13*Settings!$B$6,-2)) -> 65800 | M13: =Engine!BP288 -> 0 | N13: =Engine!BO288 -> Protected by electorates | O13: =IF(G13="No",IF(K13<=Settings!$B$9,"Below 5% but within reach","Below 5% — vote doesn't win a seat"),IF(K13<=Settings!$B$7,"Very close to +1 seat",IF(K13<=Settings!$B$8,"Close to +1 seat",IF(K13<=Settings!$B$9,"Possible +1 seat","Not near a seat")))) -> Not near a seat | P13: =IF(G13="Yes",COUNTIFS($G$8:$G$14,"Yes",$K$8:$K$14,"<"&K13)+1,"") -> 7 | Q13: =Settings!D19 -> Opposition
A14: Opportunity | B14: OPP | C14: =IF($C$3="Average",N(Polls!N37),IFERROR(N(INDEX(Polls!N$6:N$35,MATCH($C$3,Polls!$A$6:$A$35,0))),0)) -> 0.061444444 | D14: 0 | E14: =MAX(0,C14+D14) -> 0.061444444 | F14: =Settings!$C$20 -> 0 | G14: =IF(Engine!BT289="Next seat","Yes","No") -> Yes | H14: =Engine!BL289 -> 7 | I14: =Engine!BM289 -> 7 | J14: =MAX(0,I14-H14) -> 0 | K14: =Engine!BN289 -> 0.00055555556 | L14: =IF(K14="","",ROUND(K14*Settings!$B$6,-2)) -> 1600 | M14: =Engine!BP289 -> 0.9327957 | N14: =Engine!BO289 -> 0.0077697262 | O14: =IF(G14="No",IF(K14<=Settings!$B$9,"Below 5% but within reach","Below 5% — vote doesn't win a seat"),IF(K14<=Settings!$B$7,"Very close to +1 seat",IF(K14<=Settings!$B$8,"Close to +1 seat",IF(K14<=Settings!$B$9,"Possible +1 seat","Not near a seat")))) -> Very close to +1 seat | P14: =IF(G14="Yes",COUNTIFS($G$8:$G$14,"Yes",$K$8:$K$14,"<"&K14)+1,"") -> 2 | Q14: =Settings!D20 -> Undeclared
A16: Total seats | I16: =SUM(I8:I14)+Settings!$B$10 -> 122 | J16: =I16-Settings!$B$4 -> 2
A17: Seats needed for a majority | I17: =INT(I16/2)+1 -> 62
A18: Other electorate winners (from Settings) | I18: =Settings!$B$10 -> 0
A20: The marginal seat
A21: Party that won the last (120th) list seat: | E21: =IFERROR(INDEX($A$8:$A$14,MATCH(Engine!E282,$B$8:$B$14,0)),"") -> NZ First
A22: Party next in line for a seat (most leverage per vote): | E22: =IFERROR(INDEX($A$8:$A$14,MATCH(Engine!F282,$B$8:$B$14,0)),"") -> National
A24: Bloc totals
A25: Bloc | C25: Seats | D25: Majority?
A26: Govt | C26: =SUMIF($Q$8:$Q$14,A26,$I$8:$I$14) -> 59 | D26: =IF(C26>=$I$17,"Yes","No") -> No
A27: Opposition | C27: =SUMIF($Q$8:$Q$14,A27,$I$8:$I$14) -> 56 | D27: =IF(C27>=$I$17,"Yes","No") -> No
A28: Undeclared | C28: =SUMIF($Q$8:$Q$14,A28,$I$8:$I$14) -> 7 | D28: =IF(C28>=$I$17,"Yes","No") -> No
A29: Bloc names come from Settings column D; edit them there.
A31: How to read this:
A32: • Gap to next seat = how many more percentage points of the total party vote the party needs before Sainte-Laguë gives it one more seat (holding everyone else's vote fixed).
A33: • The smallest gap among parties in Parliament is where an extra party vote is most likely to turn into an extra seat. That party is 'next in line'.
A34: • For a party under 5% with no electorate, the gap is to the threshold instead. Crossing it brings in a whole block of MPs at once (about 6), but every vote below it elects nobody.
A35: • Overhang parties (more electorates than list entitlement) gain nothing from extra party votes until their entitlement passes their electorate count.
A36: • Poll error is ±2–3 pp per party, far bigger than most seat gaps. Treat this as 'where the margin sits', not a prediction.

Sheet Poll-by-Poll
A1: Poll-by-poll: seats, and how close each party is to its next seat
A2: Each poll run through the same Sainte-Laguë engine. Gap columns are pp of total party vote (threshold gap for sub-5% parties without an electorate). Greener = closer.
A5: Poll ID | B5: Pollster | C5: Fieldwork end | D5: Included? | E5: NAT seats | F5: LAB seats | G5: GRN seats | H5: ACT seats | I5: NZF seats | J5: TPM seats | K5: OPP seats | L5: Total seats | M5: Last seat to | N5: Next in line | O5: NAT gap | P5: LAB gap | Q5: GRN gap | R5: ACT gap | S5: NZF gap | T5: TPM gap | U5: OPP gap
A6: =IF(Polls!A6="","",Polls!A6) -> Verian 12 Oct | B6: =IF(Polls!B6="","",Polls!B6) -> 1News–Verian | C6: =IF(Polls!D6="","",Polls!D6) -> 46307 | D6: =IF(Polls!P6="","",Polls!P6) -> Y | E6: =IF(Engine!$B$3=1,Engine!BM4,"") -> 34 | F6: =IF(Engine!$B$3=1,Engine!BM5,"") -> 34 | G6: =IF(Engine!$B$3=1,Engine!BM6,"") -> 18 | H6: =IF(Engine!$B$3=1,Engine!BM7,"") -> 12 | I6: =IF(Engine!$B$3=1,Engine!BM8,"") -> 12 | J6: =IF(Engine!$B$3=1,Engine!BM9,"") -> 4 | K6: =IF(Engine!$B$3=1,Engine!BM10,"") -> 10 | L6: =Engine!G3 -> 124 | M6: =Engine!E3 -> NAT | N6: =Engine!F3 -> NAT | O6: =IF(Engine!$B$3=1,Engine!BN4,"") -> 0.008358209 | P6: =IF(Engine!$B$3=1,Engine!BN5,"") -> 0.008358209 | Q6: =IF(Engine!$B$3=1,Engine!BN6,"") -> 0.0046268657 | R6: =IF(Engine!$B$3=1,Engine!BN7,"") -> 0.0044776119 | S6: =IF(Engine!$B$3=1,Engine!BN8,"") -> 0.0044776119 | T6: =IF(Engine!$B$3=1,Engine!BN9,"") -> 0.03361194 | U6: =IF(Engine!$B$3=1,Engine!BN10,"") -> 0.007761194
A7: =IF(Polls!A7="","",Polls!A7) -> Curia Oct | B7: =IF(Polls!B7="","",Polls!B7) -> Taxpayers' Union–Curia | C7: =IF(Polls!D7="","",Polls!D7) -> 46300 | D7: =IF(Polls!P7="","",Polls!P7) -> Y | E7: =IF(Engine!$B$12=1,Engine!BM13,"") -> 37 | F7: =IF(Engine!$B$12=1,Engine!BM14,"") -> 36 | G7: =IF(Engine!$B$12=1,Engine!BM15,"") -> 17 | H7: =IF(Engine!$B$12=1,Engine!BM16,"") -> 12 | I7: =IF(Engine!$B$12=1,Engine!BM17,"") -> 16 | J7: =IF(Engine!$B$12=1,Engine!BM18,"") -> 4 | K7: =IF(Engine!$B$12=1,Engine!BM19,"") -> 0 | L7: =Engine!G12 -> 122 | M7: =Engine!E12 -> NZF | N7: =Engine!F12 -> LAB | O7: =IF(Engine!$B$12=1,Engine!BN13,"") -> 0.0053225806 | P7: =IF(Engine!$B$12=1,Engine!BN14,"") -> 0.00058064516 | Q7: =IF(Engine!$B$12=1,Engine!BN15,"") -> 0.002483871 | R7: =IF(Engine!$B$12=1,Engine!BN16,"") -> 0.0047741935 | S7: =IF(Engine!$B$12=1,Engine!BN17,"") -> 0.0077419355 | T7: =IF(Engine!$B$12=1,Engine!BN18,"") -> 0.02083871 | U7: =IF(Engine!$B$12=1,Engine!BN19,"") -> 0.002
A8: =IF(Polls!A8="","",Polls!A8) -> Verian 5 Oct | B8: =IF(Polls!B8="","",Polls!B8) -> 1News–Verian | C8: =IF(Polls!D8="","",Polls!D8) -> 46300 | D8: =IF(Polls!P8="","",Polls!P8) -> Y | E8: =IF(Engine!$B$21=1,Engine!BM22,"") -> 35 | F8: =IF(Engine!$B$21=1,Engine!BM23,"") -> 34 | G8: =IF(Engine!$B$21=1,Engine!BM24,"") -> 19 | H8: =IF(Engine!$B$21=1,Engine!BM25,"") -> 11 | I8: =IF(Engine!$B$21=1,Engine!BM26,"") -> 12 | J8: =IF(Engine!$B$21=1,Engine!BM27,"") -> 4 | K8: =IF(Engine!$B$21=1,Engine!BM28,"") -> 8 | L8: =Engine!G21 -> 123 | M8: =Engine!E21 -> LAB | N8: =Engine!F21 -> OPP | O8: =IF(Engine!$B$21=1,Engine!BN22,"") -> 0.0067164179 | P8: =IF(Engine!$B$21=1,Engine!BN23,"") -> 0.008358209 | Q8: =IF(Engine!$B$21=1,Engine!BN24,"") -> 0.0029850746 | R8: =IF(Engine!$B$21=1,Engine!BN25,"") -> 0.006119403 | S8: =IF(Engine!$B$21=1,Engine!BN26,"") -> 0.0044776119 | T8: =IF(Engine!$B$21=1,Engine!BN27,"") -> 0.03161194 | U8: =IF(Engine!$B$21=1,Engine!BN28,"") -> 0.0010447761
A9: =IF(Polls!A9="","",Polls!A9) -> Reid Oct | B9: =IF(Polls!B9="","",Polls!B9) -> RNZ–Reid Research | C9: =IF(Polls!D9="","",Polls!D9) -> 46296 | D9: =IF(Polls!P9="","",Polls!P9) -> Y | E9: =IF(Engine!$B$30=1,Engine!BM31,"") -> 32 | F9: =IF(Engine!$B$30=1,Engine!BM32,"") -> 37 | G9: =IF(Engine!$B$30=1,Engine!BM33,"") -> 18 | H9: =IF(Engine!$B$30=1,Engine!BM34,"") -> 11 | I9: =IF(Engine!$B$30=1,Engine!BM35,"") -> 13 | J9: =IF(Engine!$B$30=1,Engine!BM36,"") -> 4 | K9: =IF(Engine!$B$30=1,Engine!BM37,"") -> 7 | L9: =Engine!G30 -> 122 | M9: =Engine!E30 -> NAT | N9: =Engine!F30 -> LAB | O9: =IF(Engine!$B$30=1,Engine!BN31,"") -> 0.0082222222 | P9: =IF(Engine!$B$30=1,Engine!BN32,"") -> 0.00033333333 | Q9: =IF(Engine!$B$30=1,Engine!BN33,"") -> 0.0041111111 | R9: =IF(Engine!$B$30=1,Engine!BN34,"") -> 0.0045555556 | S9: =IF(Engine!$B$30=1,Engine!BN35,"") -> 0.005 | T9: =IF(Engine!$B$30=1,Engine!BN36,"") -> 0.0225 | U9: =IF(Engine!$B$30=1,Engine!BN37,"") -> 0.0066666667
A10: =IF(Polls!A10="","",Polls!A10) -> Verian 27 Sep | B10: =IF(Polls!B10="","",Polls!B10) -> 1News–Verian | C10: =IF(Polls!D10="","",Polls!D10) -> 46292 | D10: =IF(Polls!P10="","",Polls!P10) -> Y | E10: =IF(Engine!$B$39=1,Engine!BM40,"") -> 34 | F10: =IF(Engine!$B$39=1,Engine!BM41,"") -> 34 | G10: =IF(Engine!$B$39=1,Engine!BM42,"") -> 20 | H10: =IF(Engine!$B$39=1,Engine!BM43,"") -> 13 | I10: =IF(Engine!$B$39=1,Engine!BM44,"") -> 11 | J10: =IF(Engine!$B$39=1,Engine!BM45,"") -> 4 | K10: =IF(Engine!$B$39=1,Engine!BM46,"") -> 7 | L10: =Engine!G39 -> 123 | M10: =Engine!E39 -> GRN | N10: =Engine!F39 -> ACT | O10: =IF(Engine!$B$39=1,Engine!BN40,"") -> 0.0030769231 | P10: =IF(Engine!$B$39=1,Engine!BN41,"") -> 0.0030769231 | Q10: =IF(Engine!$B$39=1,Engine!BN42,"") -> 0.0082051282 | R10: =IF(Engine!$B$39=1,Engine!BN43,"") -> 0.00076923077 | S10: =IF(Engine!$B$39=1,Engine!BN44,"") -> 0.0043589744 | T10: =IF(Engine!$B$39=1,Engine!BN45,"") -> 0.024923077 | U10: =IF(Engine!$B$39=1,Engine!BN46,"") -> 0.0015384615
A11: =IF(Polls!A11="","",Polls!A11) -> Roy Morgan Sep | B11: =IF(Polls!B11="","",Polls!B11) -> Roy Morgan | C11: =IF(Polls!D11="","",Polls!D11) -> 46292 | D11: =IF(Polls!P11="","",Polls!P11) -> Y | E11: =IF(Engine!$B$48=1,Engine!BM49,"") -> 38 | F11: =IF(Engine!$B$48=1,Engine!BM50,"") -> 28 | G11: =IF(Engine!$B$48=1,Engine!BM51,"") -> 19 | H11: =IF(Engine!$B$48=1,Engine!BM52,"") -> 13 | I11: =IF(Engine!$B$48=1,Engine!BM53,"") -> 12 | J11: =IF(Engine!$B$48=1,Engine!BM54,"") -> 4 | K11: =IF(Engine!$B$48=1,Engine!BM55,"") -> 8 | L11: =Engine!G48 -> 122 | M11: =Engine!E48 -> NAT | N11: =Engine!F48 -> LAB | O11: =IF(Engine!$B$48=1,Engine!BN49,"") -> 0.0082666667 | P11: =IF(Engine!$B$48=1,Engine!BN50,"") -> 0.0006 | Q11: =IF(Engine!$B$48=1,Engine!BN51,"") -> 0.0012 | R11: =IF(Engine!$B$48=1,Engine!BN52,"") -> 0.0016 | S11: =IF(Engine!$B$48=1,Engine!BN53,"") -> 0.0033333333 | T11: =IF(Engine!$B$48=1,Engine!BN54,"") -> 0.0172 | U11: =IF(Engine!$B$48=1,Engine!BN55,"") -> 0.0052666667
A12: =IF(Polls!A12="","",Polls!A12) -> Freshwater Sep | B12: =IF(Polls!B12="","",Polls!B12) -> The Post/Freshwater Strategy | C12: =IF(Polls!D12="","",Polls!D12) -> 46276 | D12: =IF(Polls!P12="","",Polls!P12) -> Y | E12: =IF(Engine!$B$57=1,Engine!BM58,"") -> 33 | F12: =IF(Engine!$B$57=1,Engine!BM59,"") -> 34 | G12: =IF(Engine!$B$57=1,Engine!BM60,"") -> 17 | H12: =IF(Engine!$B$57=1,Engine!BM61,"") -> 11 | I12: =IF(Engine!$B$57=1,Engine!BM62,"") -> 16 | J12: =IF(Engine!$B$57=1,Engine!BM63,"") -> 4 | K12: =IF(Engine!$B$57=1,Engine!BM64,"") -> 7 | L12: =Engine!G57 -> 122 | M12: =Engine!E57 -> NAT | N12: =Engine!F57 -> LAB | O12: =IF(Engine!$B$57=1,Engine!BN58,"") -> 0.0083076923 | P12: =IF(Engine!$B$57=1,Engine!BN59,"") -> 0.0066153846 | Q12: =IF(Engine!$B$57=1,Engine!BN60,"") -> 0.0053846154 | R12: =IF(Engine!$B$57=1,Engine!BN61,"") -> 0.0055384615 | S12: =IF(Engine!$B$57=1,Engine!BN62,"") -> 0.0070769231 | T12: =IF(Engine!$B$57=1,Engine!BN63,"") -> 0.017384615 | U12: =IF(Engine!$B$57=1,Engine!BN64,"") -> 0.0023076923
A13: =IF(Polls!A13="","",Polls!A13) -> Anacta Sep | B13: =IF(Polls!B13="","",Polls!B13) -> Anacta | C13: =IF(Polls!D13="","",Polls!D13) -> 46275 | D13: =IF(Polls!P13="","",Polls!P13) -> Y | E13: =IF(Engine!$B$66=1,Engine!BM67,"") -> 36 | F13: =IF(Engine!$B$66=1,Engine!BM68,"") -> 37 | G13: =IF(Engine!$B$66=1,Engine!BM69,"") -> 15 | H13: =IF(Engine!$B$66=1,Engine!BM70,"") -> 10 | I13: =IF(Engine!$B$66=1,Engine!BM71,"") -> 12 | J13: =IF(Engine!$B$66=1,Engine!BM72,"") -> 4 | K13: =IF(Engine!$B$66=1,Engine!BM73,"") -> 8 | L13: =Engine!G66 -> 122 | M13: =Engine!E66 -> GRN | N13: =Engine!F66 -> LAB | O13: =IF(Engine!$B$66=1,Engine!BN67,"") -> 0.0020689655 | P13: =IF(Engine!$B$66=1,Engine!BN68,"") -> 0.00034482759 | Q13: =IF(Engine!$B$66=1,Engine!BN69,"") -> 0.0082758621 | R13: =IF(Engine!$B$66=1,Engine!BN70,"") -> 0.0068965517 | S13: =IF(Engine!$B$66=1,Engine!BN71,"") -> 0.0034482759 | T13: =IF(Engine!$B$66=1,Engine!BN72,"") -> 0.017241379 | U13: =IF(Engine!$B$66=1,Engine!BN73,"") -> 0.00034482759
A14: =IF(Polls!A14="","",Polls!A14) -> Curia Sep | B14: =IF(Polls!B14="","",Polls!B14) -> Taxpayers' Union–Curia | C14: =IF(Polls!D14="","",Polls!D14) -> 46268 | D14: =IF(Polls!P14="","",Polls!P14) -> Y | E14: =IF(Engine!$B$75=1,Engine!BM76,"") -> 39 | F14: =IF(Engine!$B$75=1,Engine!BM77,"") -> 34 | G14: =IF(Engine!$B$75=1,Engine!BM78,"") -> 19 | H14: =IF(Engine!$B$75=1,Engine!BM79,"") -> 14 | I14: =IF(Engine!$B$75=1,Engine!BM80,"") -> 11 | J14: =IF(Engine!$B$75=1,Engine!BM81,"") -> 4 | K14: =IF(Engine!$B$75=1,Engine!BM82,"") -> 0 | L14: =Engine!G75 -> 121 | M14: =Engine!E75 -> GRN | N14: =Engine!F75 -> LAB | O14: =IF(Engine!$B$75=1,Engine!BN76,"") -> 0.0067837838 | P14: =IF(Engine!$B$75=1,Engine!BN77,"") -> 0.00021621622 | Q14: =IF(Engine!$B$75=1,Engine!BN78,"") -> 0.0075135135 | R14: =IF(Engine!$B$75=1,Engine!BN79,"") -> 0.0039459459 | S14: =IF(Engine!$B$75=1,Engine!BN80,"") -> 0.0024054054 | T14: =IF(Engine!$B$75=1,Engine!BN81,"") -> 0.013810811 | U14: =IF(Engine!$B$75=1,Engine!BN82,"") -> 0.005
A15: =IF(Polls!A15="","",Polls!A15) -> Roy Morgan Aug | B15: =IF(Polls!B15="","",Polls!B15) -> Roy Morgan | C15: =IF(Polls!D15="","",Polls!D15) -> 46257 | D15: =IF(Polls!P15="","",Polls!P15) -> N | E15: =IF(Engine!$B$84=1,Engine!BM85,"") -> 37 | F15: =IF(Engine!$B$84=1,Engine!BM86,"") -> 29 | G15: =IF(Engine!$B$84=1,Engine!BM87,"") -> 19 | H15: =IF(Engine!$B$84=1,Engine!BM88,"") -> 13 | I15: =IF(Engine!$B$84=1,Engine!BM89,"") -> 9 | J15: =IF(Engine!$B$84=1,Engine!BM90,"") -> 4 | K15: =IF(Engine!$B$84=1,Engine!BM91,"") -> 11 | L15: =Engine!G84 -> 122 | M15: =Engine!E84 -> GRN | N15: =Engine!F84 -> NAT | O15: =IF(Engine!$B$84=1,Engine!BN85,"") -> 0.0041891892 | P15: =IF(Engine!$B$84=1,Engine!BN86,"") -> 0.0071621622 | Q15: =IF(Engine!$B$84=1,Engine!BN87,"") -> 0.0083783784 | R15: =IF(Engine!$B$84=1,Engine!BN88,"") -> 0.0081081081 | S15: =IF(Engine!$B$84=1,Engine!BN89,"") -> 0.0045945946 | T15: =IF(Engine!$B$84=1,Engine!BN90,"") -> 0.022702703 | U15: =IF(Engine!$B$84=1,Engine!BN91,"") -> 0.0013513514
A16: =IF(Polls!A16="","",Polls!A16) -> Reid Aug | B16: =IF(Polls!B16="","",Polls!B16) -> RNZ–Reid Research | C16: =IF(Polls!D16="","",Polls!D16) -> 46255 | D16: =IF(Polls!P16="","",Polls!P16) -> N | E16: =IF(Engine!$B$93=1,Engine!BM94,"") -> 35 | F16: =IF(Engine!$B$93=1,Engine!BM95,"") -> 39 | G16: =IF(Engine!$B$93=1,Engine!BM96,"") -> 12 | H16: =IF(Engine!$B$93=1,Engine!BM97,"") -> 9 | I16: =IF(Engine!$B$93=1,Engine!BM98,"") -> 15 | J16: =IF(Engine!$B$93=1,Engine!BM99,"") -> 4 | K16: =IF(Engine!$B$93=1,Engine!BM100,"") -> 6 | L16: =Engine!G93 -> 120 | M16: =Engine!E93 -> NZF | N16: =Engine!F93 -> NAT | O16: =IF(Engine!$B$93=1,Engine!BN94,"") -> 0.00034482759 | P16: =IF(Engine!$B$93=1,Engine!BN95,"") -> 0.0021724138 | Q16: =IF(Engine!$B$93=1,Engine!BN96,"") -> 0.0005862069 | R16: =IF(Engine!$B$93=1,Engine!BN97,"") -> 0.00096551724 | S16: =IF(Engine!$B$93=1,Engine!BN98,"") -> 0.0082068966 | T16: =IF(Engine!$B$93=1,Engine!BN99,"") -> 0.0069310345 | U16: =IF(Engine!$B$93=1,Engine!BN100,"") -> 0.00034482759
A17: =IF(Polls!A17="","",Polls!A17) -> Verian Aug | B17: =IF(Polls!B17="","",Polls!B17) -> 1News–Verian | C17: =IF(Polls!D17="","",Polls!D17) -> 46245 | D17: =IF(Polls!P17="","",Polls!P17) -> N | E17: =IF(Engine!$B$102=1,Engine!BM103,"") -> 36 | F17: =IF(Engine!$B$102=1,Engine!BM104,"") -> 37 | G17: =IF(Engine!$B$102=1,Engine!BM105,"") -> 15 | H17: =IF(Engine!$B$102=1,Engine!BM106,"") -> 11 | I17: =IF(Engine!$B$102=1,Engine!BM107,"") -> 10 | J17: =IF(Engine!$B$102=1,Engine!BM108,"") -> 4 | K17: =IF(Engine!$B$102=1,Engine!BM109,"") -> 10 | L17: =Engine!G102 -> 123 | M17: =Engine!E102 -> NAT | N17: =Engine!F102 -> LAB | O17: =IF(Engine!$B$102=1,Engine!BN103,"") -> 0.0081690141 | P17: =IF(Engine!$B$102=1,Engine!BN104,"") -> 0.0063380282 | Q17: =IF(Engine!$B$102=1,Engine!BN105,"") -> 0.0066197183 | R17: =IF(Engine!$B$102=1,Engine!BN106,"") -> 0.003943662 | S17: =IF(Engine!$B$102=1,Engine!BN107,"") -> 0.0057746479 | T17: =IF(Engine!$B$102=1,Engine!BN108,"") -> 0.025760563 | U17: =IF(Engine!$B$102=1,Engine!BN109,"") -> 0.0057746479
A18: =IF(Polls!A18="","",Polls!A18) -> Talbot Mills Aug | B18: =IF(Polls!B18="","",Polls!B18) -> Talbot Mills | C18: =IF(Polls!D18="","",Polls!D18) -> 46245 | D18: =IF(Polls!P18="","",Polls!P18) -> N | E18: =IF(Engine!$B$111=1,Engine!BM112,"") -> 35 | F18: =IF(Engine!$B$111=1,Engine!BM113,"") -> 41 | G18: =IF(Engine!$B$111=1,Engine!BM114,"") -> 10 | H18: =IF(Engine!$B$111=1,Engine!BM115,"") -> 8 | I18: =IF(Engine!$B$111=1,Engine!BM116,"") -> 16 | J18: =IF(Engine!$B$111=1,Engine!BM117,"") -> 4 | K18: =IF(Engine!$B$111=1,Engine!BM118,"") -> 6 | L18: =Engine!G111 -> 120 | M18: =Engine!E111 -> NZF | N18: =Engine!F111 -> ACT | O18: =IF(Engine!$B$111=1,Engine!BN112,"") -> 0.0077419355 | P18: =IF(Engine!$B$111=1,Engine!BN113,"") -> 0.0080645161 | Q18: =IF(Engine!$B$111=1,Engine!BN114,"") -> 0.0080645161 | R18: =IF(Engine!$B$111=1,Engine!BN115,"") -> 0.0012903226 | S18: =IF(Engine!$B$111=1,Engine!BN116,"") -> 0.0083870968 | T18: =IF(Engine!$B$111=1,Engine!BN117,"") -> 0.0077419355 | U18: =IF(Engine!$B$111=1,Engine!BN118,"") -> 0.002516129
A19: =IF(Polls!A19="","",Polls!A19) -> Curia Aug | B19: =IF(Polls!B19="","",Polls!B19) -> Taxpayers' Union–Curia | C19: =IF(Polls!D19="","",Polls!D19) -> 46238 | D19: =IF(Polls!P19="","",Polls!P19) -> N | E19: =IF(Engine!$B$120=1,Engine!BM121,"") -> 40 | F19: =IF(Engine!$B$120=1,Engine!BM122,"") -> 36 | G19: =IF(Engine!$B$120=1,Engine!BM123,"") -> 13 | H19: =IF(Engine!$B$120=1,Engine!BM124,"") -> 9 | I19: =IF(Engine!$B$120=1,Engine!BM125,"") -> 12 | J19: =IF(Engine!$B$120=1,Engine!BM126,"") -> 4 | K19: =IF(Engine!$B$120=1,Engine!BM127,"") -> 8 | L19: =Engine!G120 -> 122 | M19: =Engine!E120 -> LAB | N19: =Engine!F120 -> ACT | O19: =IF(Engine!$B$120=1,Engine!BN121,"") -> 0.0071549296 | P19: =IF(Engine!$B$120=1,Engine!BN122,"") -> 0.0078309859 | Q19: =IF(Engine!$B$120=1,Engine!BN123,"") -> 0.0047183099 | R19: =IF(Engine!$B$120=1,Engine!BN124,"") -> 0.0013943662 | S19: =IF(Engine!$B$120=1,Engine!BN125,"") -> 0.0068873239 | T19: =IF(Engine!$B$120=1,Engine!BN126,"") -> 0.020239437 | U19: =IF(Engine!$B$120=1,Engine!BN127,"") -> 0.0055633803
A20: =IF(Polls!A20="","",Polls!A20) | B20: =IF(Polls!B20="","",Polls!B20) | C20: =IF(Polls!D20="","",Polls!D20) | D20: =IF(Polls!P20="","",Polls!P20) | E20: =IF(Engine!$B$129=1,Engine!BM130,"") -> 34 | F20: =IF(Engine!$B$129=1,Engine!BM131,"") -> 34 | G20: =IF(Engine!$B$129=1,Engine!BM132,"") -> 18 | H20: =IF(Engine!$B$129=1,Engine!BM133,"") -> 12 | I20: =IF(Engine!$B$129=1,Engine!BM134,"") -> 13 | J20: =IF(Engine!$B$129=1,Engine!BM135,"") -> 4 | K20: =IF(Engine!$B$129=1,Engine!BM136,"") -> 7 | L20: =Engine!G129 -> 122 | M20: =Engine!E129 -> NZF | N20: =Engine!F129 -> NAT | O20: =IF(Engine!$B$129=1,Engine!BN130,"") -> 0.00031111111 | P20: =IF(Engine!$B$129=1,Engine!BN131,"") -> 0.0058666667 | Q20: =IF(Engine!$B$129=1,Engine!BN132,"") -> 0.0073777778 | R20: =IF(Engine!$B$129=1,Engine!BN133,"") -> 0.007 | S20: =IF(Engine!$B$129=1,Engine!BN134,"") -> 0.0082666667 | T20: =IF(Engine!$B$129=1,Engine!BN135,"") -> 0.0227 | U20: =IF(Engine!$B$129=1,Engine!BN136,"") -> 0.00055555556
A21: =IF(Polls!A21="","",Polls!A21) | B21: =IF(Polls!B21="","",Polls!B21) | C21: =IF(Polls!D21="","",Polls!D21) | D21: =IF(Polls!P21="","",Polls!P21) | E21: =IF(Engine!$B$138=1,Engine!BM139,"") -> 34 | F21: =IF(Engine!$B$138=1,Engine!BM140,"") -> 34 | G21: =IF(Engine!$B$138=1,Engine!BM141,"") -> 18 | H21: =IF(Engine!$B$138=1,Engine!BM142,"") -> 12 | I21: =IF(Engine!$B$138=1,Engine!BM143,"") -> 13 | J21: =IF(Engine!$B$138=1,Engine!BM144,"") -> 4 | K21: =IF(Engine!$B$138=1,Engine!BM145,"") -> 7 | L21: =Engine!G138 -> 122 | M21: =Engine!E138 -> NZF | N21: =Engine!F138 -> NAT | O21: =IF(Engine!$B$138=1,Engine!BN139,"") -> 0.00031111111 | P21: =IF(Engine!$B$138=1,Engine!BN140,"") -> 0.0058666667 | Q21: =IF(Engine!$B$138=1,Engine!BN141,"") -> 0.0073777778 | R21: =IF(Engine!$B$138=1,Engine!BN142,"") -> 0.007 | S21: =IF(Engine!$B$138=1,Engine!BN143,"") -> 0.0082666667 | T21: =IF(Engine!$B$138=1,Engine!BN144,"") -> 0.0227 | U21: =IF(Engine!$B$138=1,Engine!BN145,"") -> 0.00055555556
A22: =IF(Polls!A22="","",Polls!A22) | B22: =IF(Polls!B22="","",Polls!B22) | C22: =IF(Polls!D22="","",Polls!D22) | D22: =IF(Polls!P22="","",Polls!P22) | E22: =IF(Engine!$B$147=1,Engine!BM148,"") -> 34 | F22: =IF(Engine!$B$147=1,Engine!BM149,"") -> 34 | G22: =IF(Engine!$B$147=1,Engine!BM150,"") -> 18 | H22: =IF(Engine!$B$147=1,Engine!BM151,"") -> 12 | I22: =IF(Engine!$B$147=1,Engine!BM152,"") -> 13 | J22: =IF(Engine!$B$147=1,Engine!BM153,"") -> 4 | K22: =IF(Engine!$B$147=1,Engine!BM154,"") -> 7 | L22: =Engine!G147 -> 122 | M22: =Engine!E147 -> NZF | N22: =Engine!F147 -> NAT | O22: =IF(Engine!$B$147=1,Engine!BN148,"") -> 0.00031111111 | P22: =IF(Engine!$B$147=1,Engine!BN149,"") -> 0.0058666667 | Q22: =IF(Engine!$B$147=1,Engine!BN150,"") -> 0.0073777778 | R22: =IF(Engine!$B$147=1,Engine!BN151,"") -> 0.007 | S22: =IF(Engine!$B$147=1,Engine!BN152,"") -> 0.0082666667 | T22: =IF(Engine!$B$147=1,Engine!BN153,"") -> 0.0227 | U22: =IF(Engine!$B$147=1,Engine!BN154,"") -> 0.00055555556
A23: =IF(Polls!A23="","",Polls!A23) | B23: =IF(Polls!B23="","",Polls!B23) | C23: =IF(Polls!D23="","",Polls!D23) | D23: =IF(Polls!P23="","",Polls!P23) | E23: =IF(Engine!$B$156=1,Engine!BM157,"") -> 34 | F23: =IF(Engine!$B$156=1,Engine!BM158,"") -> 34 | G23: =IF(Engine!$B$156=1,Engine!BM159,"") -> 18 | H23: =IF(Engine!$B$156=1,Engine!BM160,"") -> 12 | I23: =IF(Engine!$B$156=1,Engine!BM161,"") -> 13 | J23: =IF(Engine!$B$156=1,Engine!BM162,"") -> 4 | K23: =IF(Engine!$B$156=1,Engine!BM163,"") -> 7 | L23: =Engine!G156 -> 122 | M23: =Engine!E156 -> NZF | N23: =Engine!F156 -> NAT | O23: =IF(Engine!$B$156=1,Engine!BN157,"") -> 0.00031111111 | P23: =IF(Engine!$B$156=1,Engine!BN158,"") -> 0.0058666667 | Q23: =IF(Engine!$B$156=1,Engine!BN159,"") -> 0.0073777778 | R23: =IF(Engine!$B$156=1,Engine!BN160,"") -> 0.007 | S23: =IF(Engine!$B$156=1,Engine!BN161,"") -> 0.0082666667 | T23: =IF(Engine!$B$156=1,Engine!BN162,"") -> 0.0227 | U23: =IF(Engine!$B$156=1,Engine!BN163,"") -> 0.00055555556
A24: =IF(Polls!A24="","",Polls!A24) | B24: =IF(Polls!B24="","",Polls!B24) | C24: =IF(Polls!D24="","",Polls!D24) | D24: =IF(Polls!P24="","",Polls!P24) | E24: =IF(Engine!$B$165=1,Engine!BM166,"") -> 34 | F24: =IF(Engine!$B$165=1,Engine!BM167,"") -> 34 | G24: =IF(Engine!$B$165=1,Engine!BM168,"") -> 18 | H24: =IF(Engine!$B$165=1,Engine!BM169,"") -> 12 | I24: =IF(Engine!$B$165=1,Engine!BM170,"") -> 13 | J24: =IF(Engine!$B$165=1,Engine!BM171,"") -> 4 | K24: =IF(Engine!$B$165=1,Engine!BM172,"") -> 7 | L24: =Engine!G165 -> 122 | M24: =Engine!E165 -> NZF | N24: =Engine!F165 -> NAT | O24: =IF(Engine!$B$165=1,Engine!BN166,"") -> 0.00031111111 | P24: =IF(Engine!$B$165=1,Engine!BN167,"") -> 0.0058666667 | Q24: =IF(Engine!$B$165=1,Engine!BN168,"") -> 0.0073777778 | R24: =IF(Engine!$B$165=1,Engine!BN169,"") -> 0.007 | S24: =IF(Engine!$B$165=1,Engine!BN170,"") -> 0.0082666667 | T24: =IF(Engine!$B$165=1,Engine!BN171,"") -> 0.0227 | U24: =IF(Engine!$B$165=1,Engine!BN172,"") -> 0.00055555556
A25: =IF(Polls!A25="","",Polls!A25) | B25: =IF(Polls!B25="","",Polls!B25) | C25: =IF(Polls!D25="","",Polls!D25) | D25: =IF(Polls!P25="","",Polls!P25) | E25: =IF(Engine!$B$174=1,Engine!BM175,"") -> 34 | F25: =IF(Engine!$B$174=1,Engine!BM176,"") -> 34 | G25: =IF(Engine!$B$174=1,Engine!BM177,"") -> 18 | H25: =IF(Engine!$B$174=1,Engine!BM178,"") -> 12 | I25: =IF(Engine!$B$174=1,Engine!BM179,"") -> 13 | J25: =IF(Engine!$B$174=1,Engine!BM180,"") -> 4 | K25: =IF(Engine!$B$174=1,Engine!BM181,"") -> 7 | L25: =Engine!G174 -> 122 | M25: =Engine!E174 -> NZF | N25: =Engine!F174 -> NAT | O25: =IF(Engine!$B$174=1,Engine!BN175,"") -> 0.00031111111 | P25: =IF(Engine!$B$174=1,Engine!BN176,"") -> 0.0058666667 | Q25: =IF(Engine!$B$174=1,Engine!BN177,"") -> 0.0073777778 | R25: =IF(Engine!$B$174=1,Engine!BN178,"") -> 0.007 | S25: =IF(Engine!$B$174=1,Engine!BN179,"") -> 0.0082666667 | T25: =IF(Engine!$B$174=1,Engine!BN180,"") -> 0.0227 | U25: =IF(Engine!$B$174=1,Engine!BN181,"") -> 0.00055555556
A26: =IF(Polls!A26="","",Polls!A26) | B26: =IF(Polls!B26="","",Polls!B26) | C26: =IF(Polls!D26="","",Polls!D26) | D26: =IF(Polls!P26="","",Polls!P26) | E26: =IF(Engine!$B$183=1,Engine!BM184,"") -> 34 | F26: =IF(Engine!$B$183=1,Engine!BM185,"") -> 34 | G26: =IF(Engine!$B$183=1,Engine!BM186,"") -> 18 | H26: =IF(Engine!$B$183=1,Engine!BM187,"") -> 12 | I26: =IF(Engine!$B$183=1,Engine!BM188,"") -> 13 | J26: =IF(Engine!$B$183=1,Engine!BM189,"") -> 4 | K26: =IF(Engine!$B$183=1,Engine!BM190,"") -> 7 | L26: =Engine!G183 -> 122 | M26: =Engine!E183 -> NZF | N26: =Engine!F183 -> NAT | O26: =IF(Engine!$B$183=1,Engine!BN184,"") -> 0.00031111111 | P26: =IF(Engine!$B$183=1,Engine!BN185,"") -> 0.0058666667 | Q26: =IF(Engine!$B$183=1,Engine!BN186,"") -> 0.0073777778 | R26: =IF(Engine!$B$183=1,Engine!BN187,"") -> 0.007 | S26: =IF(Engine!$B$183=1,Engine!BN188,"") -> 0.0082666667 | T26: =IF(Engine!$B$183=1,Engine!BN189,"") -> 0.0227 | U26: =IF(Engine!$B$183=1,Engine!BN190,"") -> 0.00055555556
A27: =IF(Polls!A27="","",Polls!A27) | B27: =IF(Polls!B27="","",Polls!B27) | C27: =IF(Polls!D27="","",Polls!D27) | D27: =IF(Polls!P27="","",Polls!P27) | E27: =IF(Engine!$B$192=1,Engine!BM193,"") -> 34 | F27: =IF(Engine!$B$192=1,Engine!BM194,"") -> 34 | G27: =IF(Engine!$B$192=1,Engine!BM195,"") -> 18 | H27: =IF(Engine!$B$192=1,Engine!BM196,"") -> 12 | I27: =IF(Engine!$B$192=1,Engine!BM197,"") -> 13 | J27: =IF(Engine!$B$192=1,Engine!BM198,"") -> 4 | K27: =IF(Engine!$B$192=1,Engine!BM199,"") -> 7 | L27: =Engine!G192 -> 122 | M27: =Engine!E192 -> NZF | N27: =Engine!F192 -> NAT | O27: =IF(Engine!$B$192=1,Engine!BN193,"") -> 0.00031111111 | P27: =IF(Engine!$B$192=1,Engine!BN194,"") -> 0.0058666667 | Q27: =IF(Engine!$B$192=1,Engine!BN195,"") -> 0.0073777778 | R27: =IF(Engine!$B$192=1,Engine!BN196,"") -> 0.007 | S27: =IF(Engine!$B$192=1,Engine!BN197,"") -> 0.0082666667 | T27: =IF(Engine!$B$192=1,Engine!BN198,"") -> 0.0227 | U27: =IF(Engine!$B$192=1,Engine!BN199,"") -> 0.00055555556
A28: =IF(Polls!A28="","",Polls!A28) | B28: =IF(Polls!B28="","",Polls!B28) | C28: =IF(Polls!D28="","",Polls!D28) | D28: =IF(Polls!P28="","",Polls!P28) | E28: =IF(Engine!$B$201=1,Engine!BM202,"") -> 34 | F28: =IF(Engine!$B$201=1,Engine!BM203,"") -> 34 | G28: =IF(Engine!$B$201=1,Engine!BM204,"") -> 18 | H28: =IF(Engine!$B$201=1,Engine!BM205,"") -> 12 | I28: =IF(Engine!$B$201=1,Engine!BM206,"") -> 13 | J28: =IF(Engine!$B$201=1,Engine!BM207,"") -> 4 | K28: =IF(Engine!$B$201=1,Engine!BM208,"") -> 7 | L28: =Engine!G201 -> 122 | M28: =Engine!E201 -> NZF | N28: =Engine!F201 -> NAT | O28: =IF(Engine!$B$201=1,Engine!BN202,"") -> 0.00031111111 | P28: =IF(Engine!$B$201=1,Engine!BN203,"") -> 0.0058666667 | Q28: =IF(Engine!$B$201=1,Engine!BN204,"") -> 0.0073777778 | R28: =IF(Engine!$B$201=1,Engine!BN205,"") -> 0.007 | S28: =IF(Engine!$B$201=1,Engine!BN206,"") -> 0.0082666667 | T28: =IF(Engine!$B$201=1,Engine!BN207,"") -> 0.0227 | U28: =IF(Engine!$B$201=1,Engine!BN208,"") -> 0.00055555556
A29: =IF(Polls!A29="","",Polls!A29) | B29: =IF(Polls!B29="","",Polls!B29) | C29: =IF(Polls!D29="","",Polls!D29) | D29: =IF(Polls!P29="","",Polls!P29) | E29: =IF(Engine!$B$210=1,Engine!BM211,"") -> 34 | F29: =IF(Engine!$B$210=1,Engine!BM212,"") -> 34 | G29: =IF(Engine!$B$210=1,Engine!BM213,"") -> 18 | H29: =IF(Engine!$B$210=1,Engine!BM214,"") -> 12 | I29: =IF(Engine!$B$210=1,Engine!BM215,"") -> 13 | J29: =IF(Engine!$B$210=1,Engine!BM216,"") -> 4 | K29: =IF(Engine!$B$210=1,Engine!BM217,"") -> 7 | L29: =Engine!G210 -> 122 | M29: =Engine!E210 -> NZF | N29: =Engine!F210 -> NAT | O29: =IF(Engine!$B$210=1,Engine!BN211,"") -> 0.00031111111 | P29: =IF(Engine!$B$210=1,Engine!BN212,"") -> 0.0058666667 | Q29: =IF(Engine!$B$210=1,Engine!BN213,"") -> 0.0073777778 | R29: =IF(Engine!$B$210=1,Engine!BN214,"") -> 0.007 | S29: =IF(Engine!$B$210=1,Engine!BN215,"") -> 0.0082666667 | T29: =IF(Engine!$B$210=1,Engine!BN216,"") -> 0.0227 | U29: =IF(Engine!$B$210=1,Engine!BN217,"") -> 0.00055555556
A30: =IF(Polls!A30="","",Polls!A30) | B30: =IF(Polls!B30="","",Polls!B30) | C30: =IF(Polls!D30="","",Polls!D30) | D30: =IF(Polls!P30="","",Polls!P30) | E30: =IF(Engine!$B$219=1,Engine!BM220,"") -> 34 | F30: =IF(Engine!$B$219=1,Engine!BM221,"") -> 34 | G30: =IF(Engine!$B$219=1,Engine!BM222,"") -> 18 | H30: =IF(Engine!$B$219=1,Engine!BM223,"") -> 12 | I30: =IF(Engine!$B$219=1,Engine!BM224,"") -> 13 | J30: =IF(Engine!$B$219=1,Engine!BM225,"") -> 4 | K30: =IF(Engine!$B$219=1,Engine!BM226,"") -> 7 | L30: =Engine!G219 -> 122 | M30: =Engine!E219 -> NZF | N30: =Engine!F219 -> NAT | O30: =IF(Engine!$B$219=1,Engine!BN220,"") -> 0.00031111111 | P30: =IF(Engine!$B$219=1,Engine!BN221,"") -> 0.0058666667 | Q30: =IF(Engine!$B$219=1,Engine!BN222,"") -> 0.0073777778 | R30: =IF(Engine!$B$219=1,Engine!BN223,"") -> 0.007 | S30: =IF(Engine!$B$219=1,Engine!BN224,"") -> 0.0082666667 | T30: =IF(Engine!$B$219=1,Engine!BN225,"") -> 0.0227 | U30: =IF(Engine!$B$219=1,Engine!BN226,"") -> 0.00055555556
A31: =IF(Polls!A31="","",Polls!A31) | B31: =IF(Polls!B31="","",Polls!B31) | C31: =IF(Polls!D31="","",Polls!D31) | D31: =IF(Polls!P31="","",Polls!P31) | E31: =IF(Engine!$B$228=1,Engine!BM229,"") -> 34 | F31: =IF(Engine!$B$228=1,Engine!BM230,"") -> 34 | G31: =IF(Engine!$B$228=1,Engine!BM231,"") -> 18 | H31: =IF(Engine!$B$228=1,Engine!BM232,"") -> 12 | I31: =IF(Engine!$B$228=1,Engine!BM233,"") -> 13 | J31: =IF(Engine!$B$228=1,Engine!BM234,"") -> 4 | K31: =IF(Engine!$B$228=1,Engine!BM235,"") -> 7 | L31: =Engine!G228 -> 122 | M31: =Engine!E228 -> NZF | N31: =Engine!F228 -> NAT | O31: =IF(Engine!$B$228=1,Engine!BN229,"") -> 0.00031111111 | P31: =IF(Engine!$B$228=1,Engine!BN230,"") -> 0.0058666667 | Q31: =IF(Engine!$B$228=1,Engine!BN231,"") -> 0.0073777778 | R31: =IF(Engine!$B$228=1,Engine!BN232,"") -> 0.007 | S31: =IF(Engine!$B$228=1,Engine!BN233,"") -> 0.0082666667 | T31: =IF(Engine!$B$228=1,Engine!BN234,"") -> 0.0227 | U31: =IF(Engine!$B$228=1,Engine!BN235,"") -> 0.00055555556
A32: =IF(Polls!A32="","",Polls!A32) | B32: =IF(Polls!B32="","",Polls!B32) | C32: =IF(Polls!D32="","",Polls!D32) | D32: =IF(Polls!P32="","",Polls!P32) | E32: =IF(Engine!$B$237=1,Engine!BM238,"") -> 34 | F32: =IF(Engine!$B$237=1,Engine!BM239,"") -> 34 | G32: =IF(Engine!$B$237=1,Engine!BM240,"") -> 18 | H32: =IF(Engine!$B$237=1,Engine!BM241,"") -> 12 | I32: =IF(Engine!$B$237=1,Engine!BM242,"") -> 13 | J32: =IF(Engine!$B$237=1,Engine!BM243,"") -> 4 | K32: =IF(Engine!$B$237=1,Engine!BM244,"") -> 7 | L32: =Engine!G237 -> 122 | M32: =Engine!E237 -> NZF | N32: =Engine!F237 -> NAT | O32: =IF(Engine!$B$237=1,Engine!BN238,"") -> 0.00031111111 | P32: =IF(Engine!$B$237=1,Engine!BN239,"") -> 0.0058666667 | Q32: =IF(Engine!$B$237=1,Engine!BN240,"") -> 0.0073777778 | R32: =IF(Engine!$B$237=1,Engine!BN241,"") -> 0.007 | S32: =IF(Engine!$B$237=1,Engine!BN242,"") -> 0.0082666667 | T32: =IF(Engine!$B$237=1,Engine!BN243,"") -> 0.0227 | U32: =IF(Engine!$B$237=1,Engine!BN244,"") -> 0.00055555556
A33: =IF(Polls!A33="","",Polls!A33) | B33: =IF(Polls!B33="","",Polls!B33) | C33: =IF(Polls!D33="","",Polls!D33) | D33: =IF(Polls!P33="","",Polls!P33) | E33: =IF(Engine!$B$246=1,Engine!BM247,"") -> 34 | F33: =IF(Engine!$B$246=1,Engine!BM248,"") -> 34 | G33: =IF(Engine!$B$246=1,Engine!BM249,"") -> 18 | H33: =IF(Engine!$B$246=1,Engine!BM250,"") -> 12 | I33: =IF(Engine!$B$246=1,Engine!BM251,"") -> 13 | J33: =IF(Engine!$B$246=1,Engine!BM252,"") -> 4 | K33: =IF(Engine!$B$246=1,Engine!BM253,"") -> 7 | L33: =Engine!G246 -> 122 | M33: =Engine!E246 -> NZF | N33: =Engine!F246 -> NAT | O33: =IF(Engine!$B$246=1,Engine!BN247,"") -> 0.00031111111 | P33: =IF(Engine!$B$246=1,Engine!BN248,"") -> 0.0058666667 | Q33: =IF(Engine!$B$246=1,Engine!BN249,"") -> 0.0073777778 | R33: =IF(Engine!$B$246=1,Engine!BN250,"") -> 0.007 | S33: =IF(Engine!$B$246=1,Engine!BN251,"") -> 0.0082666667 | T33: =IF(Engine!$B$246=1,Engine!BN252,"") -> 0.0227 | U33: =IF(Engine!$B$246=1,Engine!BN253,"") -> 0.00055555556
A34: =IF(Polls!A34="","",Polls!A34) | B34: =IF(Polls!B34="","",Polls!B34) | C34: =IF(Polls!D34="","",Polls!D34) | D34: =IF(Polls!P34="","",Polls!P34) | E34: =IF(Engine!$B$255=1,Engine!BM256,"") -> 34 | F34: =IF(Engine!$B$255=1,Engine!BM257,"") -> 34 | G34: =IF(Engine!$B$255=1,Engine!BM258,"") -> 18 | H34: =IF(Engine!$B$255=1,Engine!BM259,"") -> 12 | I34: =IF(Engine!$B$255=1,Engine!BM260,"") -> 13 | J34: =IF(Engine!$B$255=1,Engine!BM261,"") -> 4 | K34: =IF(Engine!$B$255=1,Engine!BM262,"") -> 7 | L34: =Engine!G255 -> 122 | M34: =Engine!E255 -> NZF | N34: =Engine!F255 -> NAT | O34: =IF(Engine!$B$255=1,Engine!BN256,"") -> 0.00031111111 | P34: =IF(Engine!$B$255=1,Engine!BN257,"") -> 0.0058666667 | Q34: =IF(Engine!$B$255=1,Engine!BN258,"") -> 0.0073777778 | R34: =IF(Engine!$B$255=1,Engine!BN259,"") -> 0.007 | S34: =IF(Engine!$B$255=1,Engine!BN260,"") -> 0.0082666667 | T34: =IF(Engine!$B$255=1,Engine!BN261,"") -> 0.0227 | U34: =IF(Engine!$B$255=1,Engine!BN262,"") -> 0.00055555556
A35: =IF(Polls!A35="","",Polls!A35) | B35: =IF(Polls!B35="","",Polls!B35) | C35: =IF(Polls!D35="","",Polls!D35) | D35: =IF(Polls!P35="","",Polls!P35) | E35: =IF(Engine!$B$264=1,Engine!BM265,"") -> 34 | F35: =IF(Engine!$B$264=1,Engine!BM266,"") -> 34 | G35: =IF(Engine!$B$264=1,Engine!BM267,"") -> 18 | H35: =IF(Engine!$B$264=1,Engine!BM268,"") -> 12 | I35: =IF(Engine!$B$264=1,Engine!BM269,"") -> 13 | J35: =IF(Engine!$B$264=1,Engine!BM270,"") -> 4 | K35: =IF(Engine!$B$264=1,Engine!BM271,"") -> 7 | L35: =Engine!G264 -> 122 | M35: =Engine!E264 -> NZF | N35: =Engine!F264 -> NAT | O35: =IF(Engine!$B$264=1,Engine!BN265,"") -> 0.00031111111 | P35: =IF(Engine!$B$264=1,Engine!BN266,"") -> 0.0058666667 | Q35: =IF(Engine!$B$264=1,Engine!BN267,"") -> 0.0073777778 | R35: =IF(Engine!$B$264=1,Engine!BN268,"") -> 0.007 | S35: =IF(Engine!$B$264=1,Engine!BN269,"") -> 0.0082666667 | T35: =IF(Engine!$B$264=1,Engine!BN270,"") -> 0.0227 | U35: =IF(Engine!$B$264=1,Engine!BN271,"") -> 0.00055555556
A38: Summary across INCLUDED polls
A39: Party | B39: Code | C39: Avg seats | D39: Avg gap to next seat (pp) | E39: # polls 'close' (gap ≤ Settings) | F39: # polls next in line | G39: # polls below threshold | H39: Share of polls next in line
A40: National | B40: NAT | C40: =IFERROR(AVERAGEIFS(E$6:E$35,$D$6:$D$35,"Y"),"") -> 35.333333 | D40: =IFERROR(AVERAGEIFS(O$6:O$35,$D$6:$D$35,"Y"),"") -> 0.0063470512 | E40: =COUNTIFS($D$6:$D$35,"Y",O$6:O$35,"<="&Settings!$B$8,E$6:E$35,">0") -> 2 | F40: =COUNTIFS($D$6:$D$35,"Y",$N$6:$N$35,B40) -> 1 | G40: =COUNTIFS($D$6:$D$35,"Y",E$6:E$35,0) -> 0 | H40: =IFERROR(F40/COUNTIF($D$6:$D$35,"Y"),"") -> 0.11111111
A41: Labour | B41: LAB | C41: =IFERROR(AVERAGEIFS(F$6:F$35,$D$6:$D$35,"Y"),"") -> 34.222222 | D41: =IFERROR(AVERAGEIFS(P$6:P$35,$D$6:$D$35,"Y"),"") -> 0.0031648609 | E41: =COUNTIFS($D$6:$D$35,"Y",P$6:P$35,"<="&Settings!$B$8,F$6:F$35,">0") -> 6 | F41: =COUNTIFS($D$6:$D$35,"Y",$N$6:$N$35,B41) -> 6 | G41: =COUNTIFS($D$6:$D$35,"Y",F$6:F$35,0) -> 0 | H41: =IFERROR(F41/COUNTIF($D$6:$D$35,"Y"),"") -> 0.66666667
A42: Green | B42: GRN | C42: =IFERROR(AVERAGEIFS(G$6:G$35,$D$6:$D$35,"Y"),"") -> 18 | D42: =IFERROR(AVERAGEIFS(Q$6:Q$35,$D$6:$D$35,"Y"),"") -> 0.0049762268 | E42: =COUNTIFS($D$6:$D$35,"Y",Q$6:Q$35,"<="&Settings!$B$8,G$6:G$35,">0") -> 5 | F42: =COUNTIFS($D$6:$D$35,"Y",$N$6:$N$35,B42) -> 0 | G42: =COUNTIFS($D$6:$D$35,"Y",G$6:G$35,0) -> 0 | H42: =IFERROR(F42/COUNTIF($D$6:$D$35,"Y"),"") -> 0
A43: ACT | B43: ACT | C43: =IFERROR(AVERAGEIFS(H$6:H$35,$D$6:$D$35,"Y"),"") -> 11.888889 | D43: =IFERROR(AVERAGEIFS(R$6:R$35,$D$6:$D$35,"Y"),"") -> 0.0042974393 | E43: =COUNTIFS($D$6:$D$35,"Y",R$6:R$35,"<="&Settings!$B$8,H$6:H$35,">0") -> 6 | F43: =COUNTIFS($D$6:$D$35,"Y",$N$6:$N$35,B43) -> 1 | G43: =COUNTIFS($D$6:$D$35,"Y",H$6:H$35,0) -> 0 | H43: =IFERROR(F43/COUNTIF($D$6:$D$35,"Y"),"") -> 0.11111111
A44: NZ First | B44: NZF | C44: =IFERROR(AVERAGEIFS(I$6:I$35,$D$6:$D$35,"Y"),"") -> 12.777778 | D44: =IFERROR(AVERAGEIFS(S$6:S$35,$D$6:$D$35,"Y"),"") -> 0.0047022302 | E44: =COUNTIFS($D$6:$D$35,"Y",S$6:S$35,"<="&Settings!$B$8,I$6:I$35,">0") -> 7 | F44: =COUNTIFS($D$6:$D$35,"Y",$N$6:$N$35,B44) -> 0 | G44: =COUNTIFS($D$6:$D$35,"Y",I$6:I$35,0) -> 0 | H44: =IFERROR(F44/COUNTIF($D$6:$D$35,"Y"),"") -> 0
...

Sheet Polls
A1: Poll tracker — party vote
A2: Add new polls in the blank rows (blue). Shares as % of decided party vote. Leave a party blank if not reported. Set Include = Y to use the poll in the average.
A3: Example row format: ID 'Curia Oct' | Pollster picked from list | '1–5 Oct 2026' | end date | sample | shares like 28.5%.
A5: Poll ID | B5: Pollster | C5: Fieldwork | D5: Fieldwork end | E5: Method (auto) | F5: Sample size | G5: Margin of error (±, 95%) | H5: NAT | I5: LAB | J5: GRN | K5: ACT | L5: NZF | M5: TPM | N5: OPP | O5: Others / unreported | P5: Include in average? (Y/N) | Q5: Source / notes
A6: Verian 12 Oct | B6: 1News–Verian | C6: 8–12 Oct 2026 | D6: 46307 | E6: =IF(B6="","",IFERROR(INDEX('Pollster Methods'!$C$5:$C$20,MATCH(B6,'Pollster Methods'!$A$5:$A$20,0)),"Not listed")) -> Half mobile phone (random dialling), half online panels | F6: 1007 | G6: =IF(N(F6)=0,"",1.96*SQRT(0.25/F6)) -> 0.030882421 | H6: 0.28 | I6: 0.28 | J6: 0.15 | K6: 0.1 | L6: 0.1 | M6: 0.004 | N6: 0.08 | O6: =IF(COUNT(H6:N6)=0,"",MAX(0,1-SUM(H6:N6))) -> 0.006 | P6: Y | Q6: 1News / RNZ, 13 Oct 2026
A7: Curia Oct | B7: Taxpayers' Union–Curia | C7: 1–5 Oct 2026 | D7: 46300 | E7: =IF(B7="","",IFERROR(INDEX('Pollster Methods'!$C$5:$C$20,MATCH(B7,'Pollster Methods'!$A$5:$A$20,0)),"Not listed")) -> Phone (landline & mobile) + online | F7: 1000 | G7: =IF(N(F7)=0,"",1.96*SQRT(0.25/F7)) -> 0.030990321 | H7: 0.285 | I7: 0.282 | J7: 0.133 | K7: 0.092 | L7: 0.12 | M7: 0.014 | N7: 0.048 | O7: =IF(COUNT(H7:N7)=0,"",MAX(0,1-SUM(H7:N7))) -> 0.026 | P7: Y | Q7: interest.co.nz, 9 Oct 2026; TPM from NZ Herald
A8: Verian 5 Oct | B8: 1News–Verian | C8: 1–5 Oct 2026 | D8: 46300 | E8: =IF(B8="","",IFERROR(INDEX('Pollster Methods'!$C$5:$C$20,MATCH(B8,'Pollster Methods'!$A$5:$A$20,0)),"Not listed")) -> Half mobile phone (random dialling), half online panels | F8: 1001 | G8: =IF(N(F8)=0,"",1.96*SQRT(0.25/F8)) -> 0.030974838 | H8: 0.29 | I8: 0.28 | J8: 0.16 | K8: 0.09 | L8: 0.1 | M8: 0.006 | N8: 0.07 | O8: =IF(COUNT(H8:N8)=0,"",MAX(0,1-SUM(H8:N8))) -> 0.004 | P8: Y | Q8: NZ Herald / The Conversation, 6 Oct 2026
A9: Reid Oct | B9: RNZ–Reid Research | C9: 24 Sep–1 Oct 2026 | D9: 46296 | E9: =IF(B9="","",IFERROR(INDEX('Pollster Methods'!$C$5:$C$20,MATCH(B9,'Pollster Methods'!$A$5:$A$20,0)),"Not listed")) -> Online | F9: 1000 | G9: =IF(N(F9)=0,"",1.96*SQRT(0.25/F9)) -> 0.030990321 | H9: 0.259 | I9: 0.308 | J9: 0.148 | K9: 0.09 | L9: 0.106 | N9: 0.055 | O9: =IF(COUNT(H9:N9)=0,"",MAX(0,1-SUM(H9:N9))) -> 0.034 | P9: Y | Q9: RNZ, 6 Oct 2026. TPM not reported in source.
A10: Verian 27 Sep | B10: 1News–Verian | C10: 23–27 Sep 2026 | D10: 46292 | E10: =IF(B10="","",IFERROR(INDEX('Pollster Methods'!$C$5:$C$20,MATCH(B10,'Pollster Methods'!$A$5:$A$20,0)),"Not listed")) -> Half mobile phone (random dialling), half online panels | F10: 1004 | G10: =IF(N(F10)=0,"",1.96*SQRT(0.25/F10)) -> 0.030928526 | H10: 0.28 | I10: 0.28 | J10: 0.16 | K10: 0.11 | L10: 0.09 | M10: 0.012 | N10: 0.06 | O10: =IF(COUNT(H10:N10)=0,"",MAX(0,1-SUM(H10:N10))) -> 0.008 | P10: Y | Q10: Wikipedia polling table
A11: Roy Morgan Sep | B11: Roy Morgan | C11: 31 Aug–27 Sep 2026 | D11: 46292 | E11: =IF(B11="","",IFERROR(INDEX('Pollster Methods'!$C$5:$C$20,MATCH(B11,'Pollster Methods'!$A$5:$A$20,0)),"Not listed")) -> Phone (landline & mobile) | F11: 859 | G11: =IF(N(F11)=0,"",1.96*SQRT(0.25/F11)) -> 0.033437169 | H11: 0.31 | I11: 0.235 | J11: 0.16 | K11: 0.11 | L11: 0.1 | M11: 0.02 | N11: 0.065 | O11: =IF(COUNT(H11:N11)=0,"",MAX(0,1-SUM(H11:N11))) -> 0 | P11: Y | Q11: roymorgan.com / Wikipedia polling table
A12: Freshwater Sep | B12: The Post/Freshwater Strategy | C12: 4–11 Sep 2026 | D12: 46276 | E12: =IF(B12="","",IFERROR(INDEX('Pollster Methods'!$C$5:$C$20,MATCH(B12,'Pollster Methods'!$A$5:$A$20,0)),"Not listed")) -> Online panel | F12: 1011 | G12: =IF(N(F12)=0,"",1.96*SQRT(0.25/F12)) -> 0.030821268 | H12: 0.27 | I12: 0.28 | J12: 0.14 | K12: 0.09 | L12: 0.13 | M12: 0.02 | N12: 0.06 | O12: =IF(COUNT(H12:N12)=0,"",MAX(0,1-SUM(H12:N12))) -> 0.01 | P12: Y | Q12: Wikipedia polling table
A13: Anacta Sep | B13: Anacta | C13: 4–10 Sep 2026 | D13: 46275 | E13: =IF(B13="","",IFERROR(INDEX('Pollster Methods'!$C$5:$C$20,MATCH(B13,'Pollster Methods'!$A$5:$A$20,0)),"Not listed")) -> Not stated | F13: 1701 | G13: =IF(N(F13)=0,"",1.96*SQRT(0.25/F13)) -> 0.023761504 | H13: 0.3 | I13: 0.31 | J13: 0.12 | K13: 0.08 | L13: 0.1 | M13: 0.02 | N13: 0.07 | O13: =IF(COUNT(H13:N13)=0,"",MAX(0,1-SUM(H13:N13))) -> 0 | P13: Y | Q13: Wikipedia polling table
A14: Curia Sep | B14: Taxpayers' Union–Curia | C14: 1–3 Sep 2026 | D14: 46268 | E14: =IF(B14="","",IFERROR(INDEX('Pollster Methods'!$C$5:$C$20,MATCH(B14,'Pollster Methods'!$A$5:$A$20,0)),"Not listed")) -> Phone (landline & mobile) + online | F14: 1000 | G14: =IF(N(F14)=0,"",1.96*SQRT(0.25/F14)) -> 0.030990321 | H14: 0.29 | I14: 0.259 | J14: 0.139 | K14: 0.105 | L14: 0.084 | M14: 0.02 | N14: 0.045 | O14: =IF(COUNT(H14:N14)=0,"",MAX(0,1-SUM(H14:N14))) -> 0.058 | P14: Y | Q14: Wikipedia polling table
A15: Roy Morgan Aug | B15: Roy Morgan | C15: 27 Jul–23 Aug 2026 | D15: 46257 | E15: =IF(B15="","",IFERROR(INDEX('Pollster Methods'!$C$5:$C$20,MATCH(B15,'Pollster Methods'!$A$5:$A$20,0)),"Not listed")) -> Phone (landline & mobile) | F15: 858 | G15: =IF(N(F15)=0,"",1.96*SQRT(0.25/F15)) -> 0.033456648 | H15: 0.31 | I15: 0.24 | J15: 0.155 | K15: 0.105 | L15: 0.075 | M15: 0.015 | N15: 0.095 | O15: =IF(COUNT(H15:N15)=0,"",MAX(0,1-SUM(H15:N15))) -> 0.005 | P15: N | Q15: Wikipedia polling table
A16: Reid Aug | B16: RNZ–Reid Research | C16: 14–21 Aug 2026 | D16: 46255 | E16: =IF(B16="","",IFERROR(INDEX('Pollster Methods'!$C$5:$C$20,MATCH(B16,'Pollster Methods'!$A$5:$A$20,0)),"Not listed")) -> Online | F16: 1000 | G16: =IF(N(F16)=0,"",1.96*SQRT(0.25/F16)) -> 0.030990321 | H16: 0.291 | I16: 0.322 | J16: 0.102 | K16: 0.077 | L16: 0.119 | M16: 0.03 | N16: 0.053 | O16: =IF(COUNT(H16:N16)=0,"",MAX(0,1-SUM(H16:N16))) -> 0.006 | P16: N | Q16: Wikipedia polling table
A17: Verian Aug | B17: 1News–Verian | C17: 8–11 Aug 2026 | D17: 46245 | E17: =IF(B17="","",IFERROR(INDEX('Pollster Methods'!$C$5:$C$20,MATCH(B17,'Pollster Methods'!$A$5:$A$20,0)),"Not listed")) -> Half mobile phone (random dialling), half online panels | F17: 847 | G17: =IF(N(F17)=0,"",1.96*SQRT(0.25/F17)) -> 0.033673199 | H17: 0.29 | I17: 0.3 | J17: 0.12 | K17: 0.09 | L17: 0.08 | M17: 0.011 | N17: 0.08 | O17: =IF(COUNT(H17:N17)=0,"",MAX(0,1-SUM(H17:N17))) -> 0.029 | P17: N | Q17: Wikipedia polling table
A18: Talbot Mills Aug | B18: Talbot Mills | C18: 1–11 Aug 2026 | D18: 46245 | E18: =IF(B18="","",IFERROR(INDEX('Pollster Methods'!$C$5:$C$20,MATCH(B18,'Pollster Methods'!$A$5:$A$20,0)),"Not listed")) -> Not consistently published | G18: =IF(N(F18)=0,"",1.96*SQRT(0.25/F18)) | H18: 0.29 | I18: 0.34 | J18: 0.08 | K18: 0.07 | L18: 0.13 | M18: 0.03 | N18: 0.052 | O18: =IF(COUNT(H18:N18)=0,"",MAX(0,1-SUM(H18:N18))) -> 0.008 | P18: N | Q18: Wikipedia polling table. Sample not published.
A19: Curia Aug | B19: Taxpayers' Union–Curia | C19: 1–4 Aug 2026 | D19: 46238 | E19: =IF(B19="","",IFERROR(INDEX('Pollster Methods'!$C$5:$C$20,MATCH(B19,'Pollster Methods'!$A$5:$A$20,0)),"Not listed")) -> Phone (landline & mobile) + online | F19: 1000 | G19: =IF(N(F19)=0,"",1.96*SQRT(0.25/F19)) -> 0.030990321 | H19: 0.31 | I19: 0.278 | J19: 0.101 | K19: 0.073 | L19: 0.091 | M19: 0.015 | N19: 0.061 | O19: =IF(COUNT(H19:N19)=0,"",MAX(0,1-SUM(H19:N19))) -> 0.071 | P19: N | Q19: Wikipedia polling table
E20: =IF(B20="","",IFERROR(INDEX('Pollster Methods'!$C$5:$C$20,MATCH(B20,'Pollster Methods'!$A$5:$A$20,0)),"Not listed")) | G20: =IF(N(F20)=0,"",1.96*SQRT(0.25/F20)) | O20: =IF(COUNT(H20:N20)=0,"",MAX(0,1-SUM(H20:N20)))
E21: =IF(B21="","",IFERROR(INDEX('Pollster Methods'!$C$5:$C$20,MATCH(B21,'Pollster Methods'!$A$5:$A$20,0)),"Not listed")) | G21: =IF(N(F21)=0,"",1.96*SQRT(0.25/F21)) | O21: =IF(COUNT(H21:N21)=0,"",MAX(0,1-SUM(H21:N21)))
E22: =IF(B22="","",IFERROR(INDEX('Pollster Methods'!$C$5:$C$20,MATCH(B22,'Pollster Methods'!$A$5:$A$20,0)),"Not listed")) | G22: =IF(N(F22)=0,"",1.96*SQRT(0.25/F22)) | O22: =IF(COUNT(H22:N22)=0,"",MAX(0,1-SUM(H22:N22)))
E23: =IF(B23="","",IFERROR(INDEX('Pollster Methods'!$C$5:$C$20,MATCH(B23,'Pollster Methods'!$A$5:$A$20,0)),"Not listed")) | G23: =IF(N(F23)=0,"",1.96*SQRT(0.25/F23)) | O23: =IF(COUNT(H23:N23)=0,"",MAX(0,1-SUM(H23:N23)))
E24: =IF(B24="","",IFERROR(INDEX('Pollster Methods'!$C$5:$C$20,MATCH(B24,'Pollster Methods'!$A$5:$A$20,0)),"Not listed")) | G24: =IF(N(F24)=0,"",1.96*SQRT(0.25/F24)) | O24: =IF(COUNT(H24:N24)=0,"",MAX(0,1-SUM(H24:N24)))
E25: =IF(B25="","",IFERROR(INDEX('Pollster Methods'!$C$5:$C$20,MATCH(B25,'Pollster Methods'!$A$5:$A$20,0)),"Not listed")) | G25: =IF(N(F25)=0,"",1.96*SQRT(0.25/F25)) | O25: =IF(COUNT(H25:N25)=0,"",MAX(0,1-SUM(H25:N25)))
E26: =IF(B26="","",IFERROR(INDEX('Pollster Methods'!$C$5:$C$20,MATCH(B26,'Pollster Methods'!$A$5:$A$20,0)),"Not listed")) | G26: =IF(N(F26)=0,"",1.96*SQRT(0.25/F26)) | O26: =IF(COUNT(H26:N26)=0,"",MAX(0,1-SUM(H26:N26)))
E27: =IF(B27="","",IFERROR(INDEX('Pollster Methods'!$C$5:$C$20,MATCH(B27,'Pollster Methods'!$A$5:$A$20,0)),"Not listed")) | G27: =IF(N(F27)=0,"",1.96*SQRT(0.25/F27)) | O27: =IF(COUNT(H27:N27)=0,"",MAX(0,1-SUM(H27:N27)))
E28: =IF(B28="","",IFERROR(INDEX('Pollster Methods'!$C$5:$C$20,MATCH(B28,'Pollster Methods'!$A$5:$A$20,0)),"Not listed")) | G28: =IF(N(F28)=0,"",1.96*SQRT(0.25/F28)) | O28: =IF(COUNT(H28:N28)=0,"",MAX(0,1-SUM(H28:N28)))
E29: =IF(B29="","",IFERROR(INDEX('Pollster Methods'!$C$5:$C$20,MATCH(B29,'Pollster Methods'!$A$5:$A$20,0)),"Not listed")) | G29: =IF(N(F29)=0,"",1.96*SQRT(0.25/F29)) | O29: =IF(COUNT(H29:N29)=0,"",MAX(0,1-SUM(H29:N29)))
E30: =IF(B30="","",IFERROR(INDEX('Pollster Methods'!$C$5:$C$20,MATCH(B30,'Pollster Methods'!$A$5:$A$20,0)),"Not listed")) | G30: =IF(N(F30)=0,"",1.96*SQRT(0.25/F30)) | O30: =IF(COUNT(H30:N30)=0,"",MAX(0,1-SUM(H30:N30)))
E31: =IF(B31="","",IFERROR(INDEX('Pollster Methods'!$C$5:$C$20,MATCH(B31,'Pollster Methods'!$A$5:$A$20,0)),"Not listed")) | G31: =IF(N(F31)=0,"",1.96*SQRT(0.25/F31)) | O31: =IF(COUNT(H31:N31)=0,"",MAX(0,1-SUM(H31:N31)))
... E35: =IF(B35="","",IFERROR(INDEX('Pollster Methods'!$C$5:$C$20,MATCH(B35,'Pollster Methods'!$A$5:$A$20,0)),"Not listed")) | G35: =IF(N(F35)=0,"",1.96*SQRT(0.25/F35)) | O35: =IF(COUNT(H35:N35)=0,"",MAX(0,1-SUM(H35:N35)))
A37: Average of included polls | F37: =COUNTIF(P6:P35,"Y") -> 9 | H37: =IFERROR(AVERAGEIFS(H6:H35,$P$6:$P$35,"Y",H6:H35,"<>"),"") -> 0.28488889 | I37: =IFERROR(AVERAGEIFS(I6:I35,$P$6:$P$35,"Y",I6:I35,"<>"),"") -> 0.27933333 | J37: =IFERROR(AVERAGEIFS(J6:J35,$P$6:$P$35,"Y",J6:J35,"<>"),"") -> 0.14555556 | K37: =IFERROR(AVERAGEIFS(K6:K35,$P$6:$P$35,"Y",K6:K35,"<>"),"") -> 0.096333333 | L37: =IFERROR(AVERAGEIFS(L6:L35,$P$6:$P$35,"Y",L6:L35,"<>"),"") -> 0.10333333 | M37: =IFERROR(AVERAGEIFS(M6:M35,$P$6:$P$35,"Y",M6:M35,"<>"),"") -> 0.0145 | N37: =IFERROR(AVERAGEIFS(N6:N35,$P$6:$P$35,"Y",N6:N35,"<>"),"") -> 0.061444444
A38: Simple (unweighted) mean. Blank cells are skipped. Where a poll leaves a party blank, the seat engine fills it with this average (matters mainly for TPM's overhang).

Sheet Pollster Methods
A1: Polling companies and how they poll
A2: 'Verified' rows are confirmed from a cited source this month; others reflect each firm's usual practice and should be checked against their latest report.
A4: Pollster | B4: Commissioned by | C4: Mode | D4: Sampling & weighting | E4: Typical sample | F4: Frequency | G4: Notes | H4: Status / source
A5: Taxpayers' Union–Curia | B5: Taxpayers' Union | C5: Phone (landline & mobile) + online | D5: Random sample of adults, weighted to adult population | E5: 1,000 | F5: Monthly | G5: Curia is no longer a member of the Research Association of NZ (RANZ). | H5: Verified: interest.co.nz, 9 Oct 2026; Wikipedia polling page
A6: 1News–Verian | B6: TVNZ (1News) | C6: Half mobile phone (random dialling), half online panels | D6: Probability mobile sample plus targeted online panel, weighted | E6: ~1,000 | F6: Weekly in final campaign weeks | G6: Formerly Colmar Brunton / Kantar Public. Reports Te Pāti Māori to 1 decimal place. | H6: Verified: 1News, 13 Oct 2026 (501 phone / 506 online)
A7: RNZ–Reid Research | B7: RNZ | C7: Online | D7: Quota sampling, weighted by age, gender and geography | E7: 1,000 | F7: Every few weeks in campaign | G7: Party vote excludes undecided and non-voters. | H7: Verified: RNZ, Oct 2026 poll
A8: Roy Morgan | B8: Roy Morgan (own) | C8: Phone (landline & mobile) | D8: NZ-wide cross-section over a 4-week window | E8: ~850–900 | F8: Monthly | G8: Long fieldwork window, so it reacts slowly to events. | H8: Verified: roymorgan.com, Sep 2026 release
A9: Talbot Mills | B9: Corporate clients (sometimes Labour) | C9: Not consistently published | D9: Not consistently published | E9: Often unpublished | F9: Monthly | G9: Labelled 'Labour–Talbot Mills' when commissioned by Labour. | H9: Check source for each poll
A10: The Post/Freshwater Strategy | B10: The Post | C10: Online panel | D10: Weighted online panel | E10: ~1,000 | F10: Irregular | G10: Publishes whole-number results. | H10: Check The Post release for details
A11: Anacta | B11: Not stated | C11: Not stated | D11: Not stated | E11: 1,701 (Sep 2026) | F11: Irregular | G11: Newer entrant; method not confirmed. | H11: Unverified

Sheet Settings
A1: Settings & assumptions
A2: Blue text = inputs you can change. Yellow = key assumptions.
H3: Scenario list (feeds dropdown)
A4: List + electorate seats (normal size of Parliament) | B4: 120 | C4: Electoral Act: 120 seats before any overhang. | H4: Average
A5: Party-vote threshold | B5: 0.05 | C5: 5% of party vote, or win 1+ electorate. | H5: =IF(Polls!A6="","",Polls!A6) -> Verian 12 Oct
A6: Estimated total party votes cast | B6: 2900000 | C6: Assumption: rough national total, used only to convert percentage-point gaps into vote counts. Edit if you have a better estimate. | H6: =IF(Polls!A7="","",Polls!A7) -> Curia Oct
A7: 'Very close' if gap to next seat ≤ | B7: 0.0025 | C7: 0.25 percentage points of the total party vote. | H7: =IF(Polls!A8="","",Polls!A8) -> Verian 5 Oct
A8: 'Close' if gap ≤ | B8: 0.005 | C8: 0.5 pp. | H8: =IF(Polls!A9="","",Polls!A9) -> Reid Oct
A9: 'Possible' if gap ≤ | B9: 0.01 | C9: 1.0 pp. Anything bigger is labelled 'Not near a seat'. | H9: =IF(Polls!A10="","",Polls!A10) -> Verian 27 Sep
A10: Electorate seats won by other parties / independents | B10: 0 | C10: e.g. if Te Tai Tokerau Party won its electorate, enter 1. Each adds an overhang seat. | H10: =IF(Polls!A11="","",Polls!A11) -> Roy Morgan Sep
H11: =IF(Polls!A12="","",Polls!A12) -> Freshwater Sep
A12: Electorate seats each party is assumed to win | H12: =IF(Polls!A13="","",Polls!A13) -> Anacta Sep
A13: Code | B13: Party | C13: Electorates assumed | D13: Bloc (your label) | E13: Why this default | H13: =IF(Polls!A14="","",Polls!A14) -> Curia Sep
A14: NAT | B14: National | C14: 0 | D14: Govt | E14: Left at 0: National's electorates are well below its list entitlement, so they don't change the seat count. | H14: =IF(Polls!A15="","",Polls!A15) -> Roy Morgan Aug
A15: LAB | B15: Labour | C15: 0 | D15: Opposition | E15: Left at 0 for the same reason as National. | H15: =IF(Polls!A16="","",Polls!A16) -> Reid Aug
A16: GRN | B16: Green | C16: 3 | D16: Opposition | E16: Assumes Greens hold Auckland Central, Rongotai and Wellington Central (common projection assumption). | H16: =IF(Polls!A17="","",Polls!A17) -> Verian Aug
A17: ACT | B17: ACT | C17: 2 | D17: Govt | E17: Assumes ACT holds Epsom and Tāmaki. | H17: =IF(Polls!A18="","",Polls!A18) -> Talbot Mills Aug
A18: NZF | B18: NZ First | C18: 0 | D18: Govt | E18: No electorates held; must clear 5%. | H18: =IF(Polls!A19="","",Polls!A19) -> Curia Aug
A19: TPM | B19: Te Pāti Māori | C19: 4 | D19: Opposition | E19: Assumes 4 Māori electorates (Hauraki-Waikato, Tāmaki Makaurau, Te Tai Hauāuru, Waiariki), per Wikipedia projection convention. Creates overhang. | H19: =IF(Polls!A20="","",Polls!A20)
A20: OPP | B20: Opportunity | C20: 0 | D20: Undeclared | E20: No electorates; must clear 5%. | H20: =IF(Polls!A21="","",Polls!A21)
H21: =IF(Polls!A22="","",Polls!A22)
A22: Bloc labels are just for adding up seats on the calculator. Change them to any grouping you like. | H22: =IF(Polls!A23="","",Polls!A23)
H23: =IF(Polls!A24="","",Polls!A24)
H24: =IF(Polls!A25="","",Polls!A25)
H25: =IF(Polls!A26="","",Polls!A26)
H26: =IF(Polls!A27="","",Polls!A27)
H27: =IF(Polls!A28="","",Polls!A28)
H28: =IF(Polls!A29="","",Polls!A29)
H29: =IF(Polls!A30="","",Polls!A30)
H30: =IF(Polls!A31="","",Polls!A31)
H31: =IF(Polls!A32="","",Polls!A32)
H32: =IF(Polls!A33="","",Polls!A33)
H33: =IF(Polls!A34="","",Polls!A34)
H34: =IF(Polls!A35="","",Polls!A35)

